WARNING 2024-01-10 04:12:43,503 log log.py 241 log_response Method Not Allowed: /audio_endpoint/
WARNING 2024-01-10 04:13:22,609 log log.py 241 log_response Method Not Allowed: /audio_endpoint/
ERROR 2024-01-10 04:14:20,892 log log.py 241 log_response Internal Server Error: /audio_endpoint/
Traceback (most recent call last):
  File "/Users/aiman/PycharmProjects/BeanHub-backend/.venv/lib/python3.10/site-packages/redis/connection.py", line 264, in connect
    sock = self.retry.call_with_retry(
  File "/Users/aiman/PycharmProjects/BeanHub-backend/.venv/lib/python3.10/site-packages/redis/retry.py", line 46, in call_with_retry
    return do()
  File "/Users/aiman/PycharmProjects/BeanHub-backend/.venv/lib/python3.10/site-packages/redis/connection.py", line 265, in <lambda>
    lambda: self._connect(), lambda error: self.disconnect(error)
  File "/Users/aiman/PycharmProjects/BeanHub-backend/.venv/lib/python3.10/site-packages/redis/connection.py", line 627, in _connect
    raise err
  File "/Users/aiman/PycharmProjects/BeanHub-backend/.venv/lib/python3.10/site-packages/redis/connection.py", line 615, in _connect
    sock.connect(socket_address)
ConnectionRefusedError: [Errno 61] Connection refused

During handling of the above exception, another exception occurred:

Traceback (most recent call last):
  File "/Users/aiman/PycharmProjects/BeanHub-backend/.venv/lib/python3.10/site-packages/django/core/handlers/exception.py", line 55, in inner
    response = get_response(request)
  File "/Users/aiman/PycharmProjects/BeanHub-backend/.venv/lib/python3.10/site-packages/django/core/handlers/base.py", line 197, in _get_response
    response = wrapped_callback(request, *callback_args, **callback_kwargs)
  File "/Users/aiman/PycharmProjects/BeanHub-backend/.venv/lib/python3.10/site-packages/django/views/decorators/csrf.py", line 65, in _view_wrapper
    return view_func(request, *args, **kwargs)
  File "/Users/aiman/PycharmProjects/BeanHub-backend/.venv/lib/python3.10/site-packages/django/views/generic/base.py", line 104, in view
    return self.dispatch(request, *args, **kwargs)
  File "/Users/aiman/PycharmProjects/BeanHub-backend/.venv/lib/python3.10/site-packages/rest_framework/views.py", line 509, in dispatch
    response = self.handle_exception(exc)
  File "/Users/aiman/PycharmProjects/BeanHub-backend/.venv/lib/python3.10/site-packages/rest_framework/views.py", line 469, in handle_exception
    self.raise_uncaught_exception(exc)
  File "/Users/aiman/PycharmProjects/BeanHub-backend/.venv/lib/python3.10/site-packages/rest_framework/views.py", line 480, in raise_uncaught_exception
    raise exc
  File "/Users/aiman/PycharmProjects/BeanHub-backend/.venv/lib/python3.10/site-packages/rest_framework/views.py", line 506, in dispatch
    response = handler(request, *args, **kwargs)
  File "/Users/aiman/PycharmProjects/BeanHub-backend/src/audio_endpoint/views.py", line 146, in post
    self.r.setex(name=f"conversation_history_{unique_id}",
  File "/Users/aiman/PycharmProjects/BeanHub-backend/.venv/lib/python3.10/site-packages/redis/commands/core.py", line 2366, in setex
    return self.execute_command("SETEX", name, time, value)
  File "/Users/aiman/PycharmProjects/BeanHub-backend/.venv/lib/python3.10/site-packages/redis/client.py", line 533, in execute_command
    conn = self.connection or pool.get_connection(command_name, **options)
  File "/Users/aiman/PycharmProjects/BeanHub-backend/.venv/lib/python3.10/site-packages/redis/connection.py", line 1086, in get_connection
    connection.connect()
  File "/Users/aiman/PycharmProjects/BeanHub-backend/.venv/lib/python3.10/site-packages/redis/connection.py", line 270, in connect
    raise ConnectionError(self._error_message(e))
redis.exceptions.ConnectionError: Error 61 connecting to localhost:6379. Connection refused.
